Workbook

Sheet Dashboard
A1: PROJECT ESTIMATION DASHBOARD
A2: Fill in the yellow fields below. All other values update automatically.
A3: PROJECT INFORMATION
A4: Project Name | C4: E-Commerce Web Application
A5: Client Name | C5: Acme Corp
A6: Start Date | C6: 2026-04-14
A7: Status | C7: Not Started
A9: KEY METRICS
A10: Total Features | B10: Total Hours | C10: Hourly Rate | D10: Project Cost | E10: Timeline (days) | F10: Est. End Date | G10: High Risks | H10: Completion %
A11: =COUNTA('Feature Breakdown'!A2:A100) | B11: ='Feature Breakdown'!C15 | C11: ='Cost Calculator'!C3 | D11: ='Cost Calculator'!C23 | E11: ='Timeline Builder'!D10 | F11: ='Timeline Builder'!D11 | G11: =COUNTIF('Risk Register'!D2:D50,">="&6) | H11: ='Feature Breakdown'!C17
A13: RISK-ADJUSTED ESTIMATES
A14: Base Timeline (days) | C14: ='Timeline Builder'!D10
A15: Risk Buffer (+20%) | C15: ='Timeline Builder'!D10*0.2
A16: Risk-Adjusted Timeline | C16: ='Timeline Builder'!D10*1.2
A17: Risk-Adjusted End Date | C17: =C6+'Timeline Builder'!D10*1.2
A19: COST SCENARIOS
A20: Best Case (0.8x) | D20: Expected (1.0x) | G20: Worst Case (1.5x)
A21: ='Cost Calculator'!D28 | D21: ='Cost Calculator'!D29 | G21: ='Cost Calculator'!D30
A23: FEATURE PRIORITY BREAKDOWN
A24: Priority | B24: Count | C24: Hours
A25: Must Have | B25: =COUNTIF('Feature Breakdown'!D2:D100,"Must Have") | C25: =SUMIF('Feature Breakdown'!D2:D100,"Must Have",'Feature Breakdown'!C2:C100)
A26: Should Have | B26: =COUNTIF('Feature Breakdown'!D2:D100,"Should Have") | C26: =SUMIF('Feature Breakdown'!D2:D100,"Should Have",'Feature Breakdown'!C2:C100)
A27: Could Have | B27: =COUNTIF('Feature Breakdown'!D2:D100,"Could Have") | C27: =SUMIF('Feature Breakdown'!D2:D100,"Could Have",'Feature Breakdown'!C2:C100)
A28: Won't Have | B28: =COUNTIF('Feature Breakdown'!D2:D100,"Won't Have") | C28: =SUMIF('Feature Breakdown'!D2:D100,"Won't Have",'Feature Breakdown'!C2:C100)

Sheet Feature Breakdown
A1: Feature Name | B1: Complexity | C1: Estimated Hours | D1: Priority | E1: Status | F1: Notes
A2: User Authentication (Login/Register) | B2: High | C2: 16 | D2: Must Have | E2: Done | F2: OAuth + email/password
A3: User Profile Page | B3: Medium | C3: 6 | D3: Must Have | E3: In Progress | F3: Avatar upload, edit details
A4: Product Listing Page | B4: Medium | C4: 8 | D4: Must Have | E4: Not Started | F4: Grid/list view, filters
A5: Shopping Cart | B5: High | C5: 14 | D5: Must Have | E5: Not Started | F5: Add/remove, qty update, persist
A6: Checkout & Payment Integration | B6: High | C6: 20 | D6: Must Have | E6: Not Started | F6: Stripe integration
A7: Search & Filtering | B7: Medium | C7: 6 | D7: Should Have | E7: Not Started | F7: Full-text search, category filter
A8: Admin Dashboard | B8: High | C8: 12 | D8: Should Have | E8: Not Started | F8: CRUD for products, orders
A9: Email Notifications | B9: Low | C9: 4 | D9: Should Have | E9: Not Started | F9: Order confirm, shipping update
A10: Product Reviews & Ratings | B10: Medium | C10: 8 | D10: Could Have | E10: Not Started | F10: Star rating, text review
A11: Wishlist / Favorites | B11: Low | C11: 3 | D11: Could Have | E11: Not Started | F11: Save items for later
A12: Social Media Sharing | B12: Low | C12: 2 | D12: Won't Have | E12: Not Started | F12: Share buttons on products
A13: Multi-language Support | B13: High | C13: 18 | D13: Won't Have | E13: Not Started | F13: i18n framework setup
A15: TOTAL ESTIMATED HOURS | C15: =SUM(C2:C13)
A16: Must-Have Hours Only | C16: =SUMIF(D2:D13,"Must Have",C2:C13)
A17: Completion % | C17: =IF(COUNTA(A2:A13)=0,0,COUNTIF(E2:E13,"Done")/COUNTA(A2:A13))

Sheet Timeline Builder
A1: Phase | B1: Start Date | C1: End Date | D1: Duration (days) | E1: Dependencies | F1: Owner | G1: Status | I1: Wk 1 | J1: Wk 2 | K1: Wk 3 | L1: Wk 4 | M1: Wk 5 | N1: Wk 6 | O1: Wk 7 | P1: Wk 8 | Q1: Wk 9 | R1: Wk 10 | S1: Wk 11 | T1: Wk 12
A2: Discovery & Requirements | B2: 2026-04-14 | C2: =B2+D2-1 | D2: 5 | E2: None | F2: Lead Dev | G2: Not Started | I2: =IF(AND(B2<>"",D2<>""),IF(AND(B$2+0<=C2,B$2+6>=B2),"X",""),"") | J2: =IF(AND(B2<>"",D2<>""),IF(AND(B$2+7<=C2,B$2+13>=B2),"X",""),"") | K2: =IF(AND(B2<>"",D2<>""),IF(AND(B$2+14<=C2,B$2+20>=B2),"X",""),"") | L2: =IF(AND(B2<>"",D2<>""),IF(AND(B$2+21<=C2,B$2+27>=B2),"X",""),"") | M2: =IF(AND(B2<>"",D2<>""),IF(AND(B$2+28<=C2,B$2+34>=B2),"X",""),"") | N2: =IF(AND(B2<>"",D2<>""),IF(AND(B$2+35<=C2,B$2+41>=B2),"X",""),"") | O2: =IF(AND(B2<>"",D2<>""),IF(AND(B$2+42<=C2,B$2+48>=B2),"X",""),"") | P2: =IF(AND(B2<>"",D2<>""),IF(AND(B$2+49<=C2,B$2+55>=B2),"X",""),"") | Q2: =IF(AND(B2<>"",D2<>""),IF(AND(B$2+56<=C2,B$2+62>=B2),"X",""),"") | R2: =IF(AND(B2<>"",D2<>""),IF(AND(B$2+63<=C2,B$2+69>=B2),"X",""),"") | S2: =IF(AND(B2<>"",D2<>""),IF(AND(B$2+70<=C2,B$2+76>=B2),"X",""),"") | T2: =IF(AND(B2<>"",D2<>""),IF(AND(B$2+77<=C2,B$2+83>=B2),"X",""),"")
A3: UI/UX Design | B3: =C2+1 | C3: =B3+D3-1 | D3: 8 | E3: Discovery | F3: Designer | G3: Not Started | I3: =IF(AND(B3<>"",D3<>""),IF(AND(B$2+0<=C3,B$2+6>=B3),"X",""),"") | J3: =IF(AND(B3<>"",D3<>""),IF(AND(B$2+7<=C3,B$2+13>=B3),"X",""),"") | K3: =IF(AND(B3<>"",D3<>""),IF(AND(B$2+14<=C3,B$2+20>=B3),"X",""),"") | L3: =IF(AND(B3<>"",D3<>""),IF(AND(B$2+21<=C3,B$2+27>=B3),"X",""),"") | M3: =IF(AND(B3<>"",D3<>""),IF(AND(B$2+28<=C3,B$2+34>=B3),"X",""),"") | N3: =IF(AND(B3<>"",D3<>""),IF(AND(B$2+35<=C3,B$2+41>=B3),"X",""),"") | O3: =IF(AND(B3<>"",D3<>""),IF(AND(B$2+42<=C3,B$2+48>=B3),"X",""),"") | P3: =IF(AND(B3<>"",D3<>""),IF(AND(B$2+49<=C3,B$2+55>=B3),"X",""),"") | Q3: =IF(AND(B3<>"",D3<>""),IF(AND(B$2+56<=C3,B$2+62>=B3),"X",""),"") | R3: =IF(AND(B3<>"",D3<>""),IF(AND(B$2+63<=C3,B$2+69>=B3),"X",""),"") | S3: =IF(AND(B3<>"",D3<>""),IF(AND(B$2+70<=C3,B$2+76>=B3),"X",""),"") | T3: =IF(AND(B3<>"",D3<>""),IF(AND(B$2+77<=C3,B$2+83>=B3),"X",""),"")
A4: Frontend Development | B4: =C3+1 | C4: =B4+D4-1 | D4: 15 | E4: Design | F4: Frontend Dev | G4: Not Started | I4: =IF(AND(B4<>"",D4<>""),IF(AND(B$2+0<=C4,B$2+6>=B4),"X",""),"") | J4: =IF(AND(B4<>"",D4<>""),IF(AND(B$2+7<=C4,B$2+13>=B4),"X",""),"") | K4: =IF(AND(B4<>"",D4<>""),IF(AND(B$2+14<=C4,B$2+20>=B4),"X",""),"") | L4: =IF(AND(B4<>"",D4<>""),IF(AND(B$2+21<=C4,B$2+27>=B4),"X",""),"") | M4: =IF(AND(B4<>"",D4<>""),IF(AND(B$2+28<=C4,B$2+34>=B4),"X",""),"") | N4: =IF(AND(B4<>"",D4<>""),IF(AND(B$2+35<=C4,B$2+41>=B4),"X",""),"") | O4: =IF(AND(B4<>"",D4<>""),IF(AND(B$2+42<=C4,B$2+48>=B4),"X",""),"") | P4: =IF(AND(B4<>"",D4<>""),IF(AND(B$2+49<=C4,B$2+55>=B4),"X",""),"") | Q4: =IF(AND(B4<>"",D4<>""),IF(AND(B$2+56<=C4,B$2+62>=B4),"X",""),"") | R4: =IF(AND(B4<>"",D4<>""),IF(AND(B$2+63<=C4,B$2+69>=B4),"X",""),"") | S4: =IF(AND(B4<>"",D4<>""),IF(AND(B$2+70<=C4,B$2+76>=B4),"X",""),"") | T4: =IF(AND(B4<>"",D4<>""),IF(AND(B$2+77<=C4,B$2+83>=B4),"X",""),"")
A5: Backend Development | B5: =C4+1 | C5: =B5+D5-1 | D5: 15 | E5: Discovery | F5: Backend Dev | G5: Not Started | I5: =IF(AND(B5<>"",D5<>""),IF(AND(B$2+0<=C5,B$2+6>=B5),"X",""),"") | J5: =IF(AND(B5<>"",D5<>""),IF(AND(B$2+7<=C5,B$2+13>=B5),"X",""),"") | K5: =IF(AND(B5<>"",D5<>""),IF(AND(B$2+14<=C5,B$2+20>=B5),"X",""),"") | L5: =IF(AND(B5<>"",D5<>""),IF(AND(B$2+21<=C5,B$2+27>=B5),"X",""),"") | M5: =IF(AND(B5<>"",D5<>""),IF(AND(B$2+28<=C5,B$2+34>=B5),"X",""),"") | N5: =IF(AND(B5<>"",D5<>""),IF(AND(B$2+35<=C5,B$2+41>=B5),"X",""),"") | O5: =IF(AND(B5<>"",D5<>""),IF(AND(B$2+42<=C5,B$2+48>=B5),"X",""),"") | P5: =IF(AND(B5<>"",D5<>""),IF(AND(B$2+49<=C5,B$2+55>=B5),"X",""),"") | Q5: =IF(AND(B5<>"",D5<>""),IF(AND(B$2+56<=C5,B$2+62>=B5),"X",""),"") | R5: =IF(AND(B5<>"",D5<>""),IF(AND(B$2+63<=C5,B$2+69>=B5),"X",""),"") | S5: =IF(AND(B5<>"",D5<>""),IF(AND(B$2+70<=C5,B$2+76>=B5),"X",""),"") | T5: =IF(AND(B5<>"",D5<>""),IF(AND(B$2+77<=C5,B$2+83>=B5),"X",""),"")
A6: Integration & Testing | B6: =C5+1 | C6: =B6+D6-1 | D6: 10 | E6: Frontend, Backend | F6: Full Team | G6: Not Started | I6: =IF(AND(B6<>"",D6<>""),IF(AND(B$2+0<=C6,B$2+6>=B6),"X",""),"") | J6: =IF(AND(B6<>"",D6<>""),IF(AND(B$2+7<=C6,B$2+13>=B6),"X",""),"") | K6: =IF(AND(B6<>"",D6<>""),IF(AND(B$2+14<=C6,B$2+20>=B6),"X",""),"") | L6: =IF(AND(B6<>"",D6<>""),IF(AND(B$2+21<=C6,B$2+27>=B6),"X",""),"") | M6: =IF(AND(B6<>"",D6<>""),IF(AND(B$2+28<=C6,B$2+34>=B6),"X",""),"") | N6: =IF(AND(B6<>"",D6<>""),IF(AND(B$2+35<=C6,B$2+41>=B6),"X",""),"") | O6: =IF(AND(B6<>"",D6<>""),IF(AND(B$2+42<=C6,B$2+48>=B6),"X",""),"") | P6: =IF(AND(B6<>"",D6<>""),IF(AND(B$2+49<=C6,B$2+55>=B6),"X",""),"") | Q6: =IF(AND(B6<>"",D6<>""),IF(AND(B$2+56<=C6,B$2+62>=B6),"X",""),"") | R6: =IF(AND(B6<>"",D6<>""),IF(AND(B$2+63<=C6,B$2+69>=B6),"X",""),"") | S6: =IF(AND(B6<>"",D6<>""),IF(AND(B$2+70<=C6,B$2+76>=B6),"X",""),"") | T6: =IF(AND(B6<>"",D6<>""),IF(AND(B$2+77<=C6,B$2+83>=B6),"X",""),"")
A7: Deployment & Launch | B7: =C6+1 | C7: =B7+D7-1 | D7: 3 | E7: Testing | F7: DevOps | G7: Not Started | I7: =IF(AND(B7<>"",D7<>""),IF(AND(B$2+0<=C7,B$2+6>=B7),"X",""),"") | J7: =IF(AND(B7<>"",D7<>""),IF(AND(B$2+7<=C7,B$2+13>=B7),"X",""),"") | K7: =IF(AND(B7<>"",D7<>""),IF(AND(B$2+14<=C7,B$2+20>=B7),"X",""),"") | L7: =IF(AND(B7<>"",D7<>""),IF(AND(B$2+21<=C7,B$2+27>=B7),"X",""),"") | M7: =IF(AND(B7<>"",D7<>""),IF(AND(B$2+28<=C7,B$2+34>=B7),"X",""),"") | N7: =IF(AND(B7<>"",D7<>""),IF(AND(B$2+35<=C7,B$2+41>=B7),"X",""),"") | O7: =IF(AND(B7<>"",D7<>""),IF(AND(B$2+42<=C7,B$2+48>=B7),"X",""),"") | P7: =IF(AND(B7<>"",D7<>""),IF(AND(B$2+49<=C7,B$2+55>=B7),"X",""),"") | Q7: =IF(AND(B7<>"",D7<>""),IF(AND(B$2+56<=C7,B$2+62>=B7),"X",""),"") | R7: =IF(AND(B7<>"",D7<>""),IF(AND(B$2+63<=C7,B$2+69>=B7),"X",""),"") | S7: =IF(AND(B7<>"",D7<>""),IF(AND(B$2+70<=C7,B$2+76>=B7),"X",""),"") | T7: =IF(AND(B7<>"",D7<>""),IF(AND(B$2+77<=C7,B$2+83>=B7),"X",""),"")
A8: Buffer | B8: =C7+1 | C8: =B8+D8-1 | D8: =ROUND(SUM(D2:D7)*0.2,0) | E8: All phases | F8: PM | G8: Not Started | I8: =IF(AND(B8<>"",D8<>""),IF(AND(B$2+0<=C8,B$2+6>=B8),"X",""),"") | J8: =IF(AND(B8<>"",D8<>""),IF(AND(B$2+7<=C8,B$2+13>=B8),"X",""),"") | K8: =IF(AND(B8<>"",D8<>""),IF(AND(B$2+14<=C8,B$2+20>=B8),"X",""),"") | L8: =IF(AND(B8<>"",D8<>""),IF(AND(B$2+21<=C8,B$2+27>=B8),"X",""),"") | M8: =IF(AND(B8<>"",D8<>""),IF(AND(B$2+28<=C8,B$2+34>=B8),"X",""),"") | N8: =IF(AND(B8<>"",D8<>""),IF(AND(B$2+35<=C8,B$2+41>=B8),"X",""),"") | O8: =IF(AND(B8<>"",D8<>""),IF(AND(B$2+42<=C8,B$2+48>=B8),"X",""),"") | P8: =IF(AND(B8<>"",D8<>""),IF(AND(B$2+49<=C8,B$2+55>=B8),"X",""),"") | Q8: =IF(AND(B8<>"",D8<>""),IF(AND(B$2+56<=C8,B$2+62>=B8),"X",""),"") | R8: =IF(AND(B8<>"",D8<>""),IF(AND(B$2+63<=C8,B$2+69>=B8),"X",""),"") | S8: =IF(AND(B8<>"",D8<>""),IF(AND(B$2+70<=C8,B$2+76>=B8),"X",""),"") | T8: =IF(AND(B8<>"",D8<>""),IF(AND(B$2+77<=C8,B$2+83>=B8),"X",""),"")
A10: TOTAL PROJECT DURATION | D10: =SUM(D2:D8)
A11: Estimated End Date | D11: =C8

Sheet Cost Calculator
A1: PRICING INPUTS
A3: Hourly Rate ($) | C3: 95
A4: Total Hours (from Features) | C4: ='Feature Breakdown'!C15
A5: Tax Rate (%) | C5: 0.1
A6: Platform Fee (%) | C6: 0.05
A7: Desired Profit Margin (%) | C7: 0.2
A10: PRICING MODELS
A11: Model | B11: Total Price | C11: Description
A12: Hourly Model | B12: =C3*C4 | C12: Hours x Rate
A13: Fixed Price Model | B13: =C3*C4*(1+C7) | C13: Hourly + Profit Margin
A14: Value-Based Model | B14: =C3*C4*(1+C7)*1.5 | C14: Fixed + 50% value premium
A17: COST BREAKDOWN (FIXED PRICE)
A18: Subtotal (Hours x Rate) | C18: =C3*C4
A19: Profit Margin | C19: =C18*C7
A20: Subtotal + Margin | C20: =C18+C19
A21: Taxes | C21: =C20*C5
A22: Platform Fees | C22: =C20*C6
A23: TOTAL PROJECT COST | C23: =C20+C21+C22
A26: WHAT-IF SCENARIOS
A27: Scenario | B27: Multiplier | C27: Hours | D27: Total Cost
A28: Best Case (optimistic) | B28: 0.8 | C28: =C4*B28 | D28: =C3*C28*(1+C7)
A29: Expected Case | B29: 1 | C29: =C4*B29 | D29: =C3*C29*(1+C7)
A30: Worst Case (pessimistic) | B30: 1.5 | C30: =C4*B30 | D30: =C3*C30*(1+C7)

Sheet Risk Register
A1: Risk Description | B1: Probability | C1: Impact | D1: Risk Score | E1: Mitigation Strategy | F1: Owner | G1: Status
A2: Scope creep - client adds features mid-project | B2: High | C2: High | D2: =IF(OR(B2="",C2=""),"",(IF(B2="Low",1,IF(B2="Medium",2,3)))*(IF(C2="Low",1,IF(C2="Medium",2,3)))) | E2: Define clear scope in contract; use change request process | F2: PM | G2: Open
A3: Key team member unavailable | B3: Medium | C3: High | D3: =IF(OR(B3="",C3=""),"",(IF(B3="Low",1,IF(B3="Medium",2,3)))*(IF(C3="Low",1,IF(C3="Medium",2,3)))) | E3: Cross-train team; document all decisions | F3: PM | G3: Open
A4: Third-party API changes or goes down | B4: Medium | C4: Medium | D4: =IF(OR(B4="",C4=""),"",(IF(B4="Low",1,IF(B4="Medium",2,3)))*(IF(C4="Low",1,IF(C4="Medium",2,3)))) | E4: Use abstraction layer; have fallback plan | F4: Lead Dev | G4: Open
A5: Client delays feedback/approvals | B5: High | C5: Medium | D5: =IF(OR(B5="",C5=""),"",(IF(B5="Low",1,IF(B5="Medium",2,3)))*(IF(C5="Low",1,IF(C5="Medium",2,3)))) | E5: Set SLA for feedback in contract; schedule regular reviews | F5: PM | G5: Open
A6: Underestimated task complexity | B6: High | C6: High | D6: =IF(OR(B6="",C6=""),"",(IF(B6="Low",1,IF(B6="Medium",2,3)))*(IF(C6="Low",1,IF(C6="Medium",2,3)))) | E6: Add 20% buffer; break tasks into smaller pieces | F6: Lead Dev | G6: Open
A7: Security vulnerability discovered | B7: Low | C7: High | D7: =IF(OR(B7="",C7=""),"",(IF(B7="Low",1,IF(B7="Medium",2,3)))*(IF(C7="Low",1,IF(C7="Medium",2,3)))) | E7: Follow OWASP guidelines; schedule security review | F7: Security | G7: Open
A8: Performance issues at scale | B8: Medium | C8: Medium | D8: =IF(OR(B8="",C8=""),"",(IF(B8="Low",1,IF(B8="Medium",2,3)))*(IF(C8="Low",1,IF(C8="Medium",2,3)))) | E8: Load test early; design for scalability from start | F8: Backend Dev | G8: Open
A9: Technology/framework learning curve | B9: Medium | C9: Low | D9: =IF(OR(B9="",C9=""),"",(IF(B9="Low",1,IF(B9="Medium",2,3)))*(IF(C9="Low",1,IF(C9="Medium",2,3)))) | E9: Allocate training time; use proven tech stack | F9: Lead Dev | G9: Open
A10: Deployment environment issues | B10: Low | C10: Medium | D10: =IF(OR(B10="",C10=""),"",(IF(B10="Low",1,IF(B10="Medium",2,3)))*(IF(C10="Low",1,IF(C10="Medium",2,3)))) | E10: Use staging environment; automate deployments | F10: DevOps | G10: Open
A11: Budget overrun | B11: Medium | C11: High | D11: =IF(OR(B11="",C11=""),"",(IF(B11="Low",1,IF(B11="Medium",2,3)))*(IF(C11="Low",1,IF(C11="Medium",2,3)))) | E11: Track hours weekly; flag at 75% budget consumed | F11: PM | G11: Open
A13: RISK SCORE MATRIX
B14: Low Impact (1) | C14: Med Impact (2) | D14: High Impact (3)
A15: High Prob (3) | B15: 3 | C15: 6 | D15: 9
A16: Med Prob (2) | B16: 2 | C16: 4 | D16: 6
A17: Low Prob (1) | B17: 1 | C17: 2 | D17: 3

Sheet Client Proposal
A1: PROJECT PROPOSAL
A3: Project: | C3: ='Dashboard'!C4
A4: Client: | C4: ='Dashboard'!C5
A5: Date: | C5: ='Dashboard'!C6
A6: Prepared by: | C6: [Your Name / Company]
A8: 1. PROJECT OVERVIEW
A9: [Describe the project goals, background, and what the client wants to achieve. Keep it concise -- 2-3 paragraphs max. Focus on business outcomes, not technical details.]
A13: 2. SCOPE OF WORK
A14: Feature | B14: Priority | C14: Estimated Hours
A15: ='Feature Breakdown'!A2 | B15: ='Feature Breakdown'!D2 | C15: ='Feature Breakdown'!C2
A16: ='Feature Breakdown'!A3 | B16: ='Feature Breakdown'!D3 | C16: ='Feature Breakdown'!C3
A17: ='Feature Breakdown'!A4 | B17: ='Feature Breakdown'!D4 | C17: ='Feature Breakdown'!C4
A18: ='Feature Breakdown'!A5 | B18: ='Feature Breakdown'!D5 | C18: ='Feature Breakdown'!C5
A19: ='Feature Breakdown'!A6 | B19: ='Feature Breakdown'!D6 | C19: ='Feature Breakdown'!C6
A20: ='Feature Breakdown'!A7 | B20: ='Feature Breakdown'!D7 | C20: ='Feature Breakdown'!C7
A21: ='Feature Breakdown'!A8 | B21: ='Feature Breakdown'!D8 | C21: ='Feature Breakdown'!C8
A22: ='Feature Breakdown'!A9 | B22: ='Feature Breakdown'!D9 | C22: ='Feature Breakdown'!C9
A23: ='Feature Breakdown'!A10 | B23: ='Feature Breakdown'!D10 | C23: ='Feature Breakdown'!C10
A24: ='Feature Breakdown'!A11 | B24: ='Feature Breakdown'!D11 | C24: ='Feature Breakdown'!C11
A26: 3. TIMELINE
A27: Phase | B27: Duration (days) | C27: Target Dates
A28: ='Timeline Builder'!A2 | B28: ='Timeline Builder'!D2 | C28: ='Timeline Builder'!B2&" - "&TEXT('Timeline Builder'!C2,"MM/DD/YYYY")
A29: ='Timeline Builder'!A3 | B29: ='Timeline Builder'!D3 | C29: ='Timeline Builder'!B3&" - "&TEXT('Timeline Builder'!C3,"MM/DD/YYYY")
A30: ='Timeline Builder'!A4 | B30: ='Timeline Builder'!D4 | C30: ='Timeline Builder'!B4&" - "&TEXT('Timeline Builder'!C4,"MM/DD/YYYY")
A31: ='Timeline Builder'!A5 | B31: ='Timeline Builder'!D5 | C31: ='Timeline Builder'!B5&" - "&TEXT('Timeline Builder'!C5,"MM/DD/YYYY")
A32: ='Timeline Builder'!A6 | B32: ='Timeline Builder'!D6 | C32: ='Timeline Builder'!B6&" - "&TEXT('Timeline Builder'!C6,"MM/DD/YYYY")
A33: ='Timeline Builder'!A7 | B33: ='Timeline Builder'!D7 | C33: ='Timeline Builder'!B7&" - "&TEXT('Timeline Builder'!C7,"MM/DD/YYYY")
A34: ='Timeline Builder'!A8 | B34: ='Timeline Builder'!D8 | C34: ='Timeline Builder'!B8&" - "&TEXT('Timeline Builder'!C8,"MM/DD/YYYY")
A37: 4. DELIVERABLES
A38: 1. Complete source code (Git repository access)
A39: 2. Deployment to production environment
A40: 3. Technical documentation and API reference
A41: 4. User guide / admin manual
A42: 5. 30 days post-launch bug fix support
A43: 6. [Add/modify deliverables as needed]
A45: 5. PRICING
A46: Total Estimated Hours | C46: ='Cost Calculator'!C4
A47: Hourly Rate | C47: ='Cost Calculator'!C3
A48: Subtotal | C48: ='Cost Calculator'!C18
A49: Profit Margin | C49: ='Cost Calculator'!C19
...
