Workbook

Sheet Setup
B1: THE 30-DAY HABIT TRACKER & GOAL DASHBOARD
B2: Track your habits, crush your goals, and see your progress.
B4: YOUR INFO
B5: Your Name:
B6: Start Date: | C6: 2026-03-18
B7: End Date (auto): | C7: =C6+29
B9: DEFINE YOUR HABITS (UP TO 8)
B10: Habit Name | C10: Category | D10: Daily Goal Description | E10: Why It Matters
A11: 1 | B11: Drink 8 glasses of water | C11: Health | D11: Drink 8 full glasses throughout the day | E11: Stay hydrated for energy & focus
A12: 2 | B12: Read for 20 minutes | C12: Learning | D12: Read a book or article for 20 min | E12: Expand knowledge & reduce stress
A13: 3 | B13: Meditate for 5 minutes | C13: Mindfulness | D13: Sit quietly and focus on breathing | E13: Reduce anxiety & improve clarity
A14: 4 | B14: Exercise 30 minutes | C14: Fitness | D14: Any physical activity for 30 min | E14: Build strength & boost mood
A15: 5 | B15: Write in journal | C15: Creative | D15: Write at least 200 words | E15: Process thoughts & track growth
A16: 6 | B16: No phone first hour | C16: Productivity | D16: Avoid phone for 1st hour after waking | E16: Start the day with intention
A17: 7 | B17: Practice a skill | C17: Learning | D17: Spend 15 min on a new skill | E17: Continuous improvement compounds
A18: 8 | B18: Connect with someone | C18: Social | D18: Call, text, or meet a friend/family | E18: Nurture meaningful relationships
B22: CATEGORY COLOR GUIDE
B23: Health | C23: Productivity | D23: Learning | E23: Mindfulness
B24: Fitness | C24: Creative | D24: Social | E24: Custom
B27: HOW TO USE THIS WORKBOOK
B28: 1. SETUP: Fill in your name, start date, and define up to 8 habits above.
B29: 2. TRACK: Go to the '30-Day Tracker' tab. Enter 1 for completed, 0 for missed. Leave future days blank.
B30: 3. DASHBOARD: Check the 'Dashboard' tab anytime to see your progress, streaks, and completion rates.
B31: 4. REVIEW: At the end of each week, use the 'Weekly Review' tab to reflect on wins and struggles.
B32: 5. IDEAS: Browse the 'Habit Ideas Bank' tab for 50+ habit suggestions if you need inspiration.
B34: TIP: Start with just 3-4 habits. You can always add more once you build consistency!
B35: TIP: Open this in the Google Sheets mobile app to track habits on the go.
B36: TIP: Share the link with a friend for accountability.

Sheet 30-Day Tracker
B1: 30-DAY HABIT TRACKER
B2: HABIT | C2: 1 | D2: 2 | E2: 3 | F2: 4 | G2: 5 | H2: 6 | I2: 7 | J2: 8 | K2: 9 | L2: 10 | M2: 11 | N2: 12 | O2: 13 | P2: 14 | Q2: 15 | R2: 16 | S2: 17 | T2: 18 | U2: 19 | V2: 20 | W2: 21 | X2: 22 | Y2: 23 | Z2: 24 | AA2: 25 | AB2: 26 | AC2: 27 | AD2: 28 | AE2: 29 | AF2: 30 | AG2: Current Streak | AH2: Best Streak | AI2: Completion %
A3: 1 | B3: =Setup!B11 | C3: 1 | D3: 1 | E3: 1 | F3: 0 | G3: 1 | AG3: =IF(COUNTA(C3:AF3)=0,0,IF(INDIRECT("R3C"&(2+COUNTA(C3:AF3)),FALSE)=1,COUNTA(C3:AF3)-IFERROR(MATCH(0,INDEX(C3:AF3,SEQUENCE(COUNTA(C3:AF3),1,COUNTA(C3:AF3),-1)),0),COUNTA(C3:AF3))+1,0)) | AH3: =IF(COUNTA(C3:AF3)=0,0,MAX(FREQUENCY(IF(C3:AF3=1,COLUMN(C3:AF3)),IF(C3:AF3<>1,COLUMN(C3:AF3))))) | AI3: =IF(COUNTA(C3:AF3)=0,"",COUNTIF(C3:AF3,1)/COUNTA(C3:AF3))
A4: 2 | B4: =Setup!B12 | C4: 1 | D4: 1 | E4: 1 | F4: 1 | G4: 1 | AG4: =IF(COUNTA(C4:AF4)=0,0,IF(INDIRECT("R4C"&(2+COUNTA(C4:AF4)),FALSE)=1,COUNTA(C4:AF4)-IFERROR(MATCH(0,INDEX(C4:AF4,SEQUENCE(COUNTA(C4:AF4),1,COUNTA(C4:AF4),-1)),0),COUNTA(C4:AF4))+1,0)) | AH4: =IF(COUNTA(C4:AF4)=0,0,MAX(FREQUENCY(IF(C4:AF4=1,COLUMN(C4:AF4)),IF(C4:AF4<>1,COLUMN(C4:AF4))))) | AI4: =IF(COUNTA(C4:AF4)=0,"",COUNTIF(C4:AF4,1)/COUNTA(C4:AF4))
A5: 3 | B5: =Setup!B13 | C5: 1 | D5: 0 | E5: 1 | F5: 1 | G5: 1 | AG5: =IF(COUNTA(C5:AF5)=0,0,IF(INDIRECT("R5C"&(2+COUNTA(C5:AF5)),FALSE)=1,COUNTA(C5:AF5)-IFERROR(MATCH(0,INDEX(C5:AF5,SEQUENCE(COUNTA(C5:AF5),1,COUNTA(C5:AF5),-1)),0),COUNTA(C5:AF5))+1,0)) | AH5: =IF(COUNTA(C5:AF5)=0,0,MAX(FREQUENCY(IF(C5:AF5=1,COLUMN(C5:AF5)),IF(C5:AF5<>1,COLUMN(C5:AF5))))) | AI5: =IF(COUNTA(C5:AF5)=0,"",COUNTIF(C5:AF5,1)/COUNTA(C5:AF5))
A6: 4 | B6: =Setup!B14 | C6: 0 | D6: 1 | E6: 1 | F6: 1 | G6: 0 | AG6: =IF(COUNTA(C6:AF6)=0,0,IF(INDIRECT("R6C"&(2+COUNTA(C6:AF6)),FALSE)=1,COUNTA(C6:AF6)-IFERROR(MATCH(0,INDEX(C6:AF6,SEQUENCE(COUNTA(C6:AF6),1,COUNTA(C6:AF6),-1)),0),COUNTA(C6:AF6))+1,0)) | AH6: =IF(COUNTA(C6:AF6)=0,0,MAX(FREQUENCY(IF(C6:AF6=1,COLUMN(C6:AF6)),IF(C6:AF6<>1,COLUMN(C6:AF6))))) | AI6: =IF(COUNTA(C6:AF6)=0,"",COUNTIF(C6:AF6,1)/COUNTA(C6:AF6))
A7: 5 | B7: =Setup!B15 | C7: 1 | D7: 1 | E7: 0 | F7: 1 | G7: 1 | AG7: =IF(COUNTA(C7:AF7)=0,0,IF(INDIRECT("R7C"&(2+COUNTA(C7:AF7)),FALSE)=1,COUNTA(C7:AF7)-IFERROR(MATCH(0,INDEX(C7:AF7,SEQUENCE(COUNTA(C7:AF7),1,COUNTA(C7:AF7),-1)),0),COUNTA(C7:AF7))+1,0)) | AH7: =IF(COUNTA(C7:AF7)=0,0,MAX(FREQUENCY(IF(C7:AF7=1,COLUMN(C7:AF7)),IF(C7:AF7<>1,COLUMN(C7:AF7))))) | AI7: =IF(COUNTA(C7:AF7)=0,"",COUNTIF(C7:AF7,1)/COUNTA(C7:AF7))
A8: 6 | B8: =Setup!B16 | C8: 1 | D8: 1 | E8: 1 | F8: 1 | G8: 0 | AG8: =IF(COUNTA(C8:AF8)=0,0,IF(INDIRECT("R8C"&(2+COUNTA(C8:AF8)),FALSE)=1,COUNTA(C8:AF8)-IFERROR(MATCH(0,INDEX(C8:AF8,SEQUENCE(COUNTA(C8:AF8),1,COUNTA(C8:AF8),-1)),0),COUNTA(C8:AF8))+1,0)) | AH8: =IF(COUNTA(C8:AF8)=0,0,MAX(FREQUENCY(IF(C8:AF8=1,COLUMN(C8:AF8)),IF(C8:AF8<>1,COLUMN(C8:AF8))))) | AI8: =IF(COUNTA(C8:AF8)=0,"",COUNTIF(C8:AF8,1)/COUNTA(C8:AF8))
A9: 7 | B9: =Setup!B17 | C9: 0 | D9: 1 | E9: 1 | F9: 0 | G9: 1 | AG9: =IF(COUNTA(C9:AF9)=0,0,IF(INDIRECT("R9C"&(2+COUNTA(C9:AF9)),FALSE)=1,COUNTA(C9:AF9)-IFERROR(MATCH(0,INDEX(C9:AF9,SEQUENCE(COUNTA(C9:AF9),1,COUNTA(C9:AF9),-1)),0),COUNTA(C9:AF9))+1,0)) | AH9: =IF(COUNTA(C9:AF9)=0,0,MAX(FREQUENCY(IF(C9:AF9=1,COLUMN(C9:AF9)),IF(C9:AF9<>1,COLUMN(C9:AF9))))) | AI9: =IF(COUNTA(C9:AF9)=0,"",COUNTIF(C9:AF9,1)/COUNTA(C9:AF9))
A10: 8 | B10: =Setup!B18 | C10: 1 | D10: 1 | E10: 1 | F10: 1 | G10: 1 | AG10: =IF(COUNTA(C10:AF10)=0,0,IF(INDIRECT("R10C"&(2+COUNTA(C10:AF10)),FALSE)=1,COUNTA(C10:AF10)-IFERROR(MATCH(0,INDEX(C10:AF10,SEQUENCE(COUNTA(C10:AF10),1,COUNTA(C10:AF10),-1)),0),COUNTA(C10:AF10))+1,0)) | AH10: =IF(COUNTA(C10:AF10)=0,0,MAX(FREQUENCY(IF(C10:AF10=1,COLUMN(C10:AF10)),IF(C10:AF10<>1,COLUMN(C10:AF10))))) | AI10: =IF(COUNTA(C10:AF10)=0,"",COUNTIF(C10:AF10,1)/COUNTA(C10:AF10))
B13: DAILY COMPLETION % | C13: =IF(COUNTA(C3:C10)=0,"",COUNTIF(C3:C10,1)/COUNTA(C3:C10)) | D13: =IF(COUNTA(C3:C10)=0,"",COUNTIF(D3:D10,1)/COUNTA(D3:D10)) | E13: =IF(COUNTA(C3:C10)=0,"",COUNTIF(E3:E10,1)/COUNTA(E3:E10)) | F13: =IF(COUNTA(C3:C10)=0,"",COUNTIF(F3:F10,1)/COUNTA(F3:F10)) | G13: =IF(COUNTA(C3:C10)=0,"",COUNTIF(G3:G10,1)/COUNTA(G3:G10)) | H13: =IF(COUNTA(C3:C10)=0,"",COUNTIF(H3:H10,1)/COUNTA(H3:H10)) | I13: =IF(COUNTA(C3:C10)=0,"",COUNTIF(I3:I10,1)/COUNTA(I3:I10)) | J13: =IF(COUNTA(C3:C10)=0,"",COUNTIF(J3:J10,1)/COUNTA(J3:J10)) | K13: =IF(COUNTA(C3:C10)=0,"",COUNTIF(K3:K10,1)/COUNTA(K3:K10)) | L13: =IF(COUNTA(C3:C10)=0,"",COUNTIF(L3:L10,1)/COUNTA(L3:L10)) | M13: =IF(COUNTA(C3:C10)=0,"",COUNTIF(M3:M10,1)/COUNTA(M3:M10)) | N13: =IF(COUNTA(C3:C10)=0,"",COUNTIF(N3:N10,1)/COUNTA(N3:N10)) | O13: =IF(COUNTA(C3:C10)=0,"",COUNTIF(O3:O10,1)/COUNTA(O3:O10)) | P13: =IF(COUNTA(C3:C10)=0,"",COUNTIF(P3:P10,1)/COUNTA(P3:P10)) | Q13: =IF(COUNTA(C3:C10)=0,"",COUNTIF(Q3:Q10,1)/COUNTA(Q3:Q10)) | R13: =IF(COUNTA(C3:C10)=0,"",COUNTIF(R3:R10,1)/COUNTA(R3:R10)) | S13: =IF(COUNTA(C3:C10)=0,"",COUNTIF(S3:S10,1)/COUNTA(S3:S10)) | T13: =IF(COUNTA(C3:C10)=0,"",COUNTIF(T3:T10,1)/COUNTA(T3:T10)) | U13: =IF(COUNTA(C3:C10)=0,"",COUNTIF(U3:U10,1)/COUNTA(U3:U10)) | V13: =IF(COUNTA(C3:C10)=0,"",COUNTIF(V3:V10,1)/COUNTA(V3:V10)) | W13: =IF(COUNTA(C3:C10)=0,"",COUNTIF(W3:W10,1)/COUNTA(W3:W10)) | X13: =IF(COUNTA(C3:C10)=0,"",COUNTIF(X3:X10,1)/COUNTA(X3:X10)) | Y13: =IF(COUNTA(C3:C10)=0,"",COUNTIF(Y3:Y10,1)/COUNTA(Y3:Y10)) | Z13: =IF(COUNTA(C3:C10)=0,"",COUNTIF(Z3:Z10,1)/COUNTA(Z3:Z10)) | AA13: =IF(COUNTA(C3:C10)=0,"",COUNTIF(AA3:AA10,1)/COUNTA(AA3:AA10)) | AB13: =IF(COUNTA(C3:C10)=0,"",COUNTIF(AB3:AB10,1)/COUNTA(AB3:AB10)) | AC13: =IF(COUNTA(C3:C10)=0,"",COUNTIF(AC3:AC10,1)/COUNTA(AC3:AC10)) | AD13: =IF(COUNTA(C3:C10)=0,"",COUNTIF(AD3:AD10,1)/COUNTA(AD3:AD10)) | AE13: =IF(COUNTA(C3:C10)=0,"",COUNTIF(AE3:AE10,1)/COUNTA(AE3:AE10)) | AF13: =IF(COUNTA(C3:C10)=0,"",COUNTIF(AF3:AF10,1)/COUNTA(AF3:AF10))
B15: DAILY NOTES / REFLECTIONS
C16: Great start! Missed the gym but stayed on track with everything else. | D16: Much better today. Got all my reading done. | E16: Tired but pushed through meditation.

Sheet Dashboard
B1: PROGRESS DASHBOARD
B2: Your habit-building journey at a glance
B4: OVERALL COMPLETION RATE | D4: DAYS COMPLETED | F4: ACTIVE HABITS
B5: =IFERROR(COUNTIF('30-Day Tracker'!C3:AF10,1)/COUNTA('30-Day Tracker'!C3:AF10),0) | D5: =IFERROR(MAX(COUNTA('30-Day Tracker'!C3:AF3),COUNTA('30-Day Tracker'!C4:AF4),COUNTA('30-Day Tracker'!C5:AF5),COUNTA('30-Day Tracker'!C6:AF6),COUNTA('30-Day Tracker'!C7:AF7),COUNTA('30-Day Tracker'!C8:AF8),COUNTA('30-Day Tracker'!C9:AF9),COUNTA('30-Day Tracker'!C10:AF10)),0)&" of 30" | F5: =COUNTA(Setup!B11:B18)
B7: PER-HABIT COMPLETION RATES
B8: Habit | C8: Completion % | D8: Current Streak | E8: Best Streak | F8: Status | G8: Visual Progress
B9: =Setup!B11 | C9: ='30-Day Tracker'!AI3 | D9: ='30-Day Tracker'!AG3 | E9: ='30-Day Tracker'!AH3 | F9: =IF(Setup!B11="","",IF('30-Day Tracker'!AI3>=0.8,"Excellent",IF('30-Day Tracker'!AI3>=0.6,"Good",IF('30-Day Tracker'!AI3>=0.4,"Fair","Needs Work")))) | G9: =IF(Setup!B11="","",REPT("|",ROUND(IFERROR('30-Day Tracker'!AI3,0)*20,0))&REPT(".",20-ROUND(IFERROR('30-Day Tracker'!AI3,0)*20,0)))
B10: =Setup!B12 | C10: ='30-Day Tracker'!AI4 | D10: ='30-Day Tracker'!AG4 | E10: ='30-Day Tracker'!AH4 | F10: =IF(Setup!B12="","",IF('30-Day Tracker'!AI4>=0.8,"Excellent",IF('30-Day Tracker'!AI4>=0.6,"Good",IF('30-Day Tracker'!AI4>=0.4,"Fair","Needs Work")))) | G10: =IF(Setup!B12="","",REPT("|",ROUND(IFERROR('30-Day Tracker'!AI4,0)*20,0))&REPT(".",20-ROUND(IFERROR('30-Day Tracker'!AI4,0)*20,0)))
B11: =Setup!B13 | C11: ='30-Day Tracker'!AI5 | D11: ='30-Day Tracker'!AG5 | E11: ='30-Day Tracker'!AH5 | F11: =IF(Setup!B13="","",IF('30-Day Tracker'!AI5>=0.8,"Excellent",IF('30-Day Tracker'!AI5>=0.6,"Good",IF('30-Day Tracker'!AI5>=0.4,"Fair","Needs Work")))) | G11: =IF(Setup!B13="","",REPT("|",ROUND(IFERROR('30-Day Tracker'!AI5,0)*20,0))&REPT(".",20-ROUND(IFERROR('30-Day Tracker'!AI5,0)*20,0)))
B12: =Setup!B14 | C12: ='30-Day Tracker'!AI6 | D12: ='30-Day Tracker'!AG6 | E12: ='30-Day Tracker'!AH6 | F12: =IF(Setup!B14="","",IF('30-Day Tracker'!AI6>=0.8,"Excellent",IF('30-Day Tracker'!AI6>=0.6,"Good",IF('30-Day Tracker'!AI6>=0.4,"Fair","Needs Work")))) | G12: =IF(Setup!B14="","",REPT("|",ROUND(IFERROR('30-Day Tracker'!AI6,0)*20,0))&REPT(".",20-ROUND(IFERROR('30-Day Tracker'!AI6,0)*20,0)))
B13: =Setup!B15 | C13: ='30-Day Tracker'!AI7 | D13: ='30-Day Tracker'!AG7 | E13: ='30-Day Tracker'!AH7 | F13: =IF(Setup!B15="","",IF('30-Day Tracker'!AI7>=0.8,"Excellent",IF('30-Day Tracker'!AI7>=0.6,"Good",IF('30-Day Tracker'!AI7>=0.4,"Fair","Needs Work")))) | G13: =IF(Setup!B15="","",REPT("|",ROUND(IFERROR('30-Day Tracker'!AI7,0)*20,0))&REPT(".",20-ROUND(IFERROR('30-Day Tracker'!AI7,0)*20,0)))
B14: =Setup!B16 | C14: ='30-Day Tracker'!AI8 | D14: ='30-Day Tracker'!AG8 | E14: ='30-Day Tracker'!AH8 | F14: =IF(Setup!B16="","",IF('30-Day Tracker'!AI8>=0.8,"Excellent",IF('30-Day Tracker'!AI8>=0.6,"Good",IF('30-Day Tracker'!AI8>=0.4,"Fair","Needs Work")))) | G14: =IF(Setup!B16="","",REPT("|",ROUND(IFERROR('30-Day Tracker'!AI8,0)*20,0))&REPT(".",20-ROUND(IFERROR('30-Day Tracker'!AI8,0)*20,0)))
B15: =Setup!B17 | C15: ='30-Day Tracker'!AI9 | D15: ='30-Day Tracker'!AG9 | E15: ='30-Day Tracker'!AH9 | F15: =IF(Setup!B17="","",IF('30-Day Tracker'!AI9>=0.8,"Excellent",IF('30-Day Tracker'!AI9>=0.6,"Good",IF('30-Day Tracker'!AI9>=0.4,"Fair","Needs Work")))) | G15: =IF(Setup!B17="","",REPT("|",ROUND(IFERROR('30-Day Tracker'!AI9,0)*20,0))&REPT(".",20-ROUND(IFERROR('30-Day Tracker'!AI9,0)*20,0)))
B16: =Setup!B18 | C16: ='30-Day Tracker'!AI10 | D16: ='30-Day Tracker'!AG10 | E16: ='30-Day Tracker'!AH10 | F16: =IF(Setup!B18="","",IF('30-Day Tracker'!AI10>=0.8,"Excellent",IF('30-Day Tracker'!AI10>=0.6,"Good",IF('30-Day Tracker'!AI10>=0.4,"Fair","Needs Work")))) | G16: =IF(Setup!B18="","",REPT("|",ROUND(IFERROR('30-Day Tracker'!AI10,0)*20,0))&REPT(".",20-ROUND(IFERROR('30-Day Tracker'!AI10,0)*20,0)))
B19: WEEKLY BREAKDOWN
B20: Week | C20: Days | D20: Completion Rate | E20: Visual
B21: Week 1 | C21: Days 1-7 | D21: =IFERROR(COUNTIF('30-Day Tracker'!C3:I10,1)/COUNTA('30-Day Tracker'!C3:I10),0) | E21: =REPT("|",ROUND(D21*20,0))&REPT(".",20-ROUND(D21*20,0))
B22: Week 2 | C22: Days 8-14 | D22: =IFERROR(COUNTIF('30-Day Tracker'!J3:P10,1)/COUNTA('30-Day Tracker'!J3:P10),0) | E22: =REPT("|",ROUND(D22*20,0))&REPT(".",20-ROUND(D22*20,0))
B23: Week 3 | C23: Days 15-21 | D23: =IFERROR(COUNTIF('30-Day Tracker'!Q3:W10,1)/COUNTA('30-Day Tracker'!Q3:W10),0) | E23: =REPT("|",ROUND(D23*20,0))&REPT(".",20-ROUND(D23*20,0))
B24: Week 4 | C24: Days 22-30 | D24: =IFERROR(COUNTIF('30-Day Tracker'!X3:AF10,1)/COUNTA('30-Day Tracker'!X3:AF10),0) | E24: =REPT("|",ROUND(D24*20,0))&REPT(".",20-ROUND(D24*20,0))
B27: CATEGORY PERFORMANCE
B28: Category | C28: Avg Completion | D28: Visual
B29: Health | C29: =IFERROR(AVERAGEIF(Setup!C11:C18,"Health",'30-Day Tracker'!AI3:AI10),"") | D29: =IF(C29="","",REPT("|",ROUND(C29*20,0))&REPT(".",20-ROUND(C29*20,0)))
B30: Productivity | C30: =IFERROR(AVERAGEIF(Setup!C11:C18,"Productivity",'30-Day Tracker'!AI3:AI10),"") | D30: =IF(C30="","",REPT("|",ROUND(C30*20,0))&REPT(".",20-ROUND(C30*20,0)))
B31: Learning | C31: =IFERROR(AVERAGEIF(Setup!C11:C18,"Learning",'30-Day Tracker'!AI3:AI10),"") | D31: =IF(C31="","",REPT("|",ROUND(C31*20,0))&REPT(".",20-ROUND(C31*20,0)))
B32: Mindfulness | C32: =IFERROR(AVERAGEIF(Setup!C11:C18,"Mindfulness",'30-Day Tracker'!AI3:AI10),"") | D32: =IF(C32="","",REPT("|",ROUND(C32*20,0))&REPT(".",20-ROUND(C32*20,0)))
B33: Fitness | C33: =IFERROR(AVERAGEIF(Setup!C11:C18,"Fitness",'30-Day Tracker'!AI3:AI10),"") | D33: =IF(C33="","",REPT("|",ROUND(C33*20,0))&REPT(".",20-ROUND(C33*20,0)))
B34: Creative | C34: =IFERROR(AVERAGEIF(Setup!C11:C18,"Creative",'30-Day Tracker'!AI3:AI10),"") | D34: =IF(C34="","",REPT("|",ROUND(C34*20,0))&REPT(".",20-ROUND(C34*20,0)))
B35: Social | C35: =IFERROR(AVERAGEIF(Setup!C11:C18,"Social",'30-Day Tracker'!AI3:AI10),"") | D35: =IF(C35="","",REPT("|",ROUND(C35*20,0))&REPT(".",20-ROUND(C35*20,0)))
B36: Custom | C36: =IFERROR(AVERAGEIF(Setup!C11:C18,"Custom",'30-Day Tracker'!AI3:AI10),"") | D36: =IF(C36="","",REPT("|",ROUND(C36*20,0))&REPT(".",20-ROUND(C36*20,0)))
B39: MILESTONE TRACKER
B40: 1 WEEK | C40: =IF(IFERROR(MAX(COUNTA('30-Day Tracker'!C3:AF3),COUNTA('30-Day Tracker'!C4:AF4),COUNTA('30-Day Tracker'!C5:AF5),COUNTA('30-Day Tracker'!C6:AF6),COUNTA('30-Day Tracker'!C7:AF7),COUNTA('30-Day Tracker'!C8:AF8),COUNTA('30-Day Tracker'!C9:AF9),COUNTA('30-Day Tracker'!C10:AF10)),0)>=7,"ACHIEVED","In Progress") | D40: You've built the foundation!
B41: 2 WEEKS | C41: =IF(IFERROR(MAX(COUNTA('30-Day Tracker'!C3:AF3),COUNTA('30-Day Tracker'!C4:AF4),COUNTA('30-Day Tracker'!C5:AF5),COUNTA('30-Day Tracker'!C6:AF6),COUNTA('30-Day Tracker'!C7:AF7),COUNTA('30-Day Tracker'!C8:AF8),COUNTA('30-Day Tracker'!C9:AF9),COUNTA('30-Day Tracker'!C10:AF10)),0)>=14,"ACHIEVED","In Progress") | D41: You're forming real habits!
B42: 3 WEEKS | C42: =IF(IFERROR(MAX(COUNTA('30-Day Tracker'!C3:AF3),COUNTA('30-Day Tracker'!C4:AF4),COUNTA('30-Day Tracker'!C5:AF5),COUNTA('30-Day Tracker'!C6:AF6),COUNTA('30-Day Tracker'!C7:AF7),COUNTA('30-Day Tracker'!C8:AF8),COUNTA('30-Day Tracker'!C9:AF9),COUNTA('30-Day Tracker'!C10:AF10)),0)>=21,"ACHIEVED","In Progress") | D42: Science says this is when habits stick!
B43: 30 DAYS | C43: =IF(IFERROR(MAX(COUNTA('30-Day Tracker'!C3:AF3),COUNTA('30-Day Tracker'!C4:AF4),COUNTA('30-Day Tracker'!C5:AF5),COUNTA('30-Day Tracker'!C6:AF6),COUNTA('30-Day Tracker'!C7:AF7),COUNTA('30-Day Tracker'!C8:AF8),COUNTA('30-Day Tracker'!C9:AF9),COUNTA('30-Day Tracker'!C10:AF10)),0)>=30,"ACHIEVED","In Progress") | D43: CONGRATULATIONS! You did it!

Sheet Weekly Review
B1: WEEKLY REVIEW & REFLECTION
B2: Take 10 minutes each week to reflect on your progress
B4: WEEK 1 REVIEW (Days 1-7)
B5: Week Completion Rate: | C5: =IFERROR(COUNTIF('30-Day Tracker'!C3:I10,1)/COUNTA('30-Day Tracker'!C3:I10),0)
B6: Habits Completed: | C6: =COUNTIF('30-Day Tracker'!C3:I10,1)&" / "&COUNTA('30-Day Tracker'!C3:I10)
B7: What went well this week?
B8: What habits did you nail? What felt easy or natural?
B9: What was challenging?
B10: Which habits did you miss? What got in the way?
B11: What will you adjust?
B12: Any habits to modify, swap, or approach differently?
B13: Focus for Next Week:
B14: What one thing will make the biggest difference?
B16: WEEK 2 REVIEW (Days 8-14)
B17: Week Completion Rate: | C17: =IFERROR(COUNTIF('30-Day Tracker'!J3:P10,1)/COUNTA('30-Day Tracker'!J3:P10),0)
B18: Habits Completed: | C18: =COUNTIF('30-Day Tracker'!J3:P10,1)&" / "&COUNTA('30-Day Tracker'!J3:P10)
B19: What went well this week?
B20: What habits did you nail? What felt easy or natural?
B21: What was challenging?
B22: Which habits did you miss? What got in the way?
B23: What will you adjust?
B24: Any habits to modify, swap, or approach differently?
B25: Focus for Next Week:
B26: What one thing will make the biggest difference?
B28: WEEK 3 REVIEW (Days 15-21)
B29: Week Completion Rate: | C29: =IFERROR(COUNTIF('30-Day Tracker'!Q3:W10,1)/COUNTA('30-Day Tracker'!Q3:W10),0)
B30: Habits Completed: | C30: =COUNTIF('30-Day Tracker'!Q3:W10,1)&" / "&COUNTA('30-Day Tracker'!Q3:W10)
B31: What went well this week?
B32: What habits did you nail? What felt easy or natural?
B33: What was challenging?
B34: Which habits did you miss? What got in the way?
B35: What will you adjust?
B36: Any habits to modify, swap, or approach differently?
B37: Focus for Next Week:
B38: What one thing will make the biggest difference?
B40: WEEK 4 REVIEW (Days 22-28)
B41: Week Completion Rate: | C41: =IFERROR(COUNTIF('30-Day Tracker'!X3:AF10,1)/COUNTA('30-Day Tracker'!X3:AF10),0)
B42: Habits Completed: | C42: =COUNTIF('30-Day Tracker'!X3:AF10,1)&" / "&COUNTA('30-Day Tracker'!X3:AF10)
B43: What went well this week?
B44: What habits did you nail? What felt easy or natural?
...

Sheet Habit Ideas Bank
B1: HABIT IDEAS BANK
B2: Browse 50+ ideas to find habits that work for you. Start with 3-4 Easy ones!
B3: Habit Idea | C3: Category | D3: Difficulty | E3: Time Needed
B4: Drink 8 glasses of water | C4: Health | D4: Easy | E4: Throughout day
B5: Sleep by 10:00 PM | C5: Health | D5: Medium | E5: N/A
B6: Eat a serving of vegetables | C6: Health | D6: Easy | E6: At meals
B7: No sugar or processed snacks | C7: Health | D7: Hard | E7: Throughout day
B8: Walk for 10 minutes | C8: Health | D8: Easy | E8: 10 min
B9: Stretch for 5 minutes | C9: Health | D9: Easy | E9: 5 min
B10: Take vitamins/supplements | C10: Health | D10: Easy | E10: 1 min
B11: No eating after 8 PM | C11: Health | D11: Medium | E11: N/A
B12: Cook a healthy meal | C12: Health | D12: Medium | E12: 30 min
B14: Plan tomorrow tonight | C14: Productivity | D14: Easy | E14: 5 min
B15: No phone for first hour | C15: Productivity | D15: Medium | E15: 60 min
... B66: Practice active listening | C66: Social | D66: Medium | E66: Throughout day
